<sdf version='1.7'>
  <model name='olympus_description'>
    <joint name='world_joint' type='fixed'>
      <pose relative_to='__model__'>0 0 1 0 -0 0</pose>
      <parent>world</parent>
      <child>Body</child>
    </joint>
    <link name='Body'>
      <pose relative_to='world_joint'>0 0 0 0 -0 0</pose>
      <inertial>
        <pose>-0.00939 0.000187 0.011109 0 -0 0</pose>
        <mass>5.679</mass>
        <inertia>
          <ixx>0.0542861</ixx>
          <ixy>-0.00110179</ixy>
          <ixz>-0.0017034</ixz>
          <iyy>0.150706</iyy>
          <iyz>0.00013585</iyz>
          <izz>0.195747</izz>
        </inertia>
      </inertial>
      <collision name='Body_collision'>
        <pose>0 0 0 0 -0 0</pose>
        <geometry>
          <mesh>
            <scale>1 1 1</scale>
            <uri>model://olympus_description/urdf/meshes/Body.STL</uri>
          </mesh>
        </geometry>
      </collision>
      <visual name='Body_visual'>
        <pose>0 0 0 0 -0 0</pose>
        <geometry>
          <mesh>
            <scale>1 1 1</scale>
            <uri>model://olympus_description/urdf/meshes/Body.STL</uri>
          </mesh>
        </geometry>
      </visual>
    </link>
    <joint name='BackLeft_motorHousing_hipAduction_motor9' type='revolute'>
      <pose relative_to='Body'>-0.1433 0.15 0 0 -0 0</pose>
      <parent>Body</parent>
      <child>BackLeft_motorHousing</child>
      <axis>
        <xyz>1 0 0</xyz>
        <limit>
          <lower>-1.57</lower>
          <upper>1.57</upper>
          <effort>0</effort>
          <velocity>0</velocity>
        </limit>
        <dynamics>
          <spring_reference>0</spring_reference>
          <spring_stiffness>0</spring_stiffness>
        </dynamics>
      </axis>
    </joint>
    <link name='BackLeft_motorHousing'>
      <pose relative_to='BackLeft_motorHousing_hipAduction_motor9'>0 0 0 0 -0 0</pose>
      <inertial>
        <pose>-0.092829 0.02913 -0.000238 0 -0 0</pose>
        <mass>1.437</mass>
        <inertia>
          <ixx>0.00232895</ixx>
          <ixy>-0.00418147</ixy>
          <ixz>3.194e-05</ixz>
          <iyy>0.0186199</iyy>
          <iyz>-4.4e-06</iyz>
          <izz>0.0194884</izz>
        </inertia>
      </inertial>
      <collision name='BackLeft_motorHousing_collision'>
        <pose>0 0 0 0 -0 0</pose>
        <geometry>
          <mesh>
            <scale>1 1 1</scale>
            <uri>model://olympus_description/urdf/meshes/BackLeft_motorHousing.STL</uri>
          </mesh>
        </geometry>
      </collision>
      <visual name='BackLeft_motorHousing_visual'>
        <pose>0 0 0 0 -0 0</pose>
        <geometry>
          <mesh>
            <scale>1 1 1</scale>
            <uri>model://olympus_description/urdf/meshes/BackLeft_motorHousing.STL</uri>
          </mesh>
        </geometry>
      </visual>
    </link>
    <joint name='BackLeft_hip_inner_motor8' type='revolute'>
      <pose relative_to='BackLeft_motorHousing'>-0.0517 0.05945 1.1e-05 0 -0 0</pose>
      <parent>BackLeft_motorHousing</parent>
      <child>BackLeft_hip_inner</child>
      <axis>
        <xyz>0 -1 0</xyz>
        <limit>
          <lower>-1.57</lower>
          <upper>1.57</upper>
          <effort>0</effort>
          <velocity>0</velocity>
        </limit>
        <dynamics>
          <spring_reference>0</spring_reference>
          <spring_stiffness>0</spring_stiffness>
        </dynamics>
      </axis>
    </joint>
    <link name='BackLeft_hip_inner'>
      <pose relative_to='BackLeft_hip_inner_motor8'>0 0 0 0 -0 0</pose>
      <inertial>
        <pose>0.000871 -0.002633 -0.059284 0 -0 0</pose>
        <mass>0.081</mass>
        <inertia>
          <ixx>0.00080451</ixx>
          <ixy>7e-08</ixy>
          <ixz>-1.097e-05</ixz>
          <iyy>0.00081035</iyy>
          <iyz>-4.68e-06</iyz>
          <izz>8.51e-06</izz>
        </inertia>
      </inertial>
      <collision name='BackLeft_hip_inner_collision'>
        <pose>0 0 0 0 -0 0</pose>
        <geometry>
          <mesh>
            <scale>1 1 1</scale>
            <uri>model://olympus_description/urdf/meshes/BackLeft_hip_inner.STL</uri>
          </mesh>
        </geometry>
      </collision>
      <visual name='BackLeft_hip_inner_visual'>
        <pose>0 0 0 0 -0 0</pose>
        <geometry>
          <mesh>
            <scale>1 1 1</scale>
            <uri>model://olympus_description/urdf/meshes/BackLeft_hip_inner.STL</uri>
          </mesh>
        </geometry>
      </visual>
    </link>
    <joint name='BackLeft_shank_inner_knee' type='revolute'>
      <pose relative_to='BackLeft_hip_inner'>0 0.00075 -0.175 0 0.156107 0</pose>
      <parent>BackLeft_hip_inner</parent>
      <child>BackLeft_shank_inner</child>
      <axis>
        <xyz>0 1 0</xyz>
        <limit>
          <lower>-1.57</lower>
          <upper>1.57</upper>
          <effort>0</effort>
          <velocity>0</velocity>
        </limit>
        <dynamics>
          <spring_reference>0</spring_reference>
          <spring_stiffness>0</spring_stiffness>
        </dynamics>
      </axis>
    </joint>
    <link name='BackLeft_shank_inner'>
      <pose relative_to='BackLeft_shank_inner_knee'>0 0 0 0 -0 0</pose>
      <inertial>
        <pose>0.019639 1e-06 -0.194268 0 -0 0</pose>
        <mass>0.2193</mass>
        <inertia>
          <ixx>0.00834295</ixx>
          <ixy>-1.29768e-07</ixy>
          <ixz>-0.000695437</ixz>
          <iyy>0.00842358</iyy>
          <iyz>1.54792e-06</iyz>
          <izz>0.00011907</izz>
        </inertia>
      </inertial>
      <collision name='BackLeft_shank_inner_collision'>
        <pose>0 0 0 0 -0 0</pose>
        <geometry>
          <mesh>
            <scale>1 1 1</scale>
            <uri>model://olympus_description/urdf/meshes/BackLeft_shank_inner.STL</uri>
          </mesh>
        </geometry>
      </collision>
      <collision name='BackLeft_shank_inner_fixed_joint_lump__BackLeft_paw_collision_1'>
        <pose>0.034316 0 -0.318287 0 0.587746 -3.14159</pose>
        <geometry>
          <mesh>
            <scale>1 1 1</scale>
            <uri>model://olympus_description/urdf/meshes/BackLeft_paw.STL</uri>
          </mesh>
        </geometry>
      </collision>
      <visual name='BackLeft_shank_inner_visual'>
        <pose>0 0 0 0 -0 0</pose>
        <geometry>
          <mesh>
            <scale>1 1 1</scale>
            <uri>model://olympus_description/urdf/meshes/BackLeft_shank_inner.STL</uri>
          </mesh>
        </geometry>
      </visual>
      <visual name='BackLeft_shank_inner_fixed_joint_lump__BackLeft_paw_visual_1'>
        <pose>0.034316 0 -0.318287 0 0.587746 -3.14159</pose>
        <geometry>
          <mesh>
            <scale>1 1 1</scale>
            <uri>model://olympus_description/urdf/meshes/BackLeft_paw.STL</uri>
          </mesh>
        </geometry>
      </visual>
    </link>
    <joint name='BackLeft_hip_outer_motor7' type='revolute'>
      <pose relative_to='BackLeft_motorHousing'>-0.1417 0.05945 1.1e-05 0 -0 0</pose>
      <parent>BackLeft_motorHousing</parent>
      <child>BackLeft_hip_outer</child>
      <axis>
        <xyz>0 -1 0</xyz>
        <limit>
          <lower>-1.57</lower>
          <upper>1.57</upper>
          <effort>0</effort>
          <velocity>0</velocity>
        </limit>
        <dynamics>
          <spring_reference>0</spring_reference>
          <spring_stiffness>0</spring_stiffness>
        </dynamics>
      </axis>
    </joint>
    <link name='BackLeft_hip_outer'>
      <pose relative_to='BackLeft_hip_outer_motor7'>0 0 0 0 -0 0</pose>
      <inertial>
        <pose>-0.000871 -0.002638 -0.059532 0 -0 0</pose>
        <mass>0.0805</mass>
        <inertia>
          <ixx>0.00080743</ixx>
          <ixy>-7e-08</ixy>
          <ixz>1.1e-05</ixz>
          <iyy>0.00081318</iyy>
          <iyz>-4.71e-06</iyz>
          <izz>8.42e-06</izz>
        </inertia>
      </inertial>
      <collision name='BackLeft_hip_outer_collision'>
        <pose>0 0 0 0 -0 0</pose>
        <geometry>
          <mesh>
            <scale>1 1 1</scale>
            <uri>model://olympus_description/urdf/meshes/BackLeft_hip_outer.STL</uri>
          </mesh>
        </geometry>
      </collision>
      <visual name='BackLeft_hip_outer_visual'>
        <pose>0 0 0 0 -0 0</pose>
        <geometry>
          <mesh>
            <scale>1 1 1</scale>
            <uri>model://olympus_description/urdf/meshes/BackLeft_hip_outer.STL</uri>
          </mesh>
        </geometry>
      </visual>
    </link>
    <joint name='BackLeft_shank_outer_knee' type='revolute'>
      <pose relative_to='BackLeft_hip_outer'>0 0.00075 -0.175 0 -0.145529 0</pose>
      <parent>BackLeft_hip_outer</parent>
      <child>BackLeft_shank_outer</child>
      <axis>
        <xyz>0 1 0</xyz>
        <limit>
          <lower>-1.57</lower>
          <upper>1.57</upper>
          <effort>0</effort>
          <velocity>0</velocity>
        </limit>
        <dynamics>
          <spring_reference>0</spring_reference>
          <spring_stiffness>0</spring_stiffness>
        </dynamics>
      </axis>
    </joint>
    <link name='BackLeft_shank_outer'>
      <pose relative_to='BackLeft_shank_outer_knee'>0 0 0 0 -0 0</pose>
      <inertial>
        <pose>-0.004475 1e-06 -0.16466 0 -0 0</pose>
        <mass>0.1992</mass>
        <inertia>
          <ixx>0.0081046</ixx>
          <ixy>3e-08</ixy>
          <ixz>8.7e-05</ixz>
          <iyy>0.00810896</iyy>
          <iyz>1.7e-06</iyz>
          <izz>2.321e-05</izz>
        </inertia>
      </inertial>
      <collision name='BackLeft_shank_outer_collision'>
        <pose>0 0 0 0 -0 0</pose>
        <geometry>
          <mesh>
            <scale>1 1 1</scale>
            <uri>model://olympus_description/urdf/meshes/BackLeft_shank_outer.STL</uri>
          </mesh>
        </geometry>
      </collision>
      <visual name='BackLeft_shank_outer_visual'>
        <pose>0 0 0 0 -0 0</pose>
        <geometry>
          <mesh>
            <scale>1 1 1</scale>
            <uri>model://olympus_description/urdf/meshes/BackLeft_shank_outer.STL</uri>
          </mesh>
        </geometry>
      </visual>
    </link>
    <joint name='BackRight_motorHousing_hipAduction_motor12' type='revolute'>
      <pose relative_to='Body'>-0.1433 -0.15 0 0 -0 0</pose>
      <parent>Body</parent>
      <child>BackRight_motorHousing</child>
      <axis>
        <xyz>1 0 0</xyz>
        <limit>
          <lower>-1.57</lower>
          <upper>1.57</upper>
          <effort>0</effort>
          <velocity>0</velocity>
        </limit>
        <dynamics>
          <spring_reference>0</spring_reference>
          <spring_stiffness>0</spring_stiffness>
        </dynamics>
      </axis>
    </joint>
    <link name='BackRight_motorHousing'>
      <pose relative_to='BackRight_motorHousing_hipAduction_motor12'>0 0 0 0 -0 0</pose>
      <inertial>
        <pose>-0.092829 -0.02913 0.000238 0 -0 0</pose>
        <mass>1.437</mass>
        <inertia>
          <ixx>0.00232895</ixx>
          <ixy>0.00418147</ixy>
          <ixz>-3.194e-05</ixz>
          <iyy>0.0186199</iyy>
          <iyz>-4.4e-06</iyz>
          <izz>0.0194884</izz>
        </inertia>
      </inertial>
      <collision name='BackRight_motorHousing_collision'>
        <pose>0 0 0 0 -0 0</pose>
        <geometry>
          <mesh>
            <scale>1 1 1</scale>
            <uri>model://olympus_description/urdf/meshes/BackRight_motorHousing.STL</uri>
          </mesh>
        </geometry>
      </collision>
      <visual name='BackRight_motorHousing_visual'>
        <pose>0 0 0 0 -0 0</pose>
        <geometry>
          <mesh>
            <scale>1 1 1</scale>
            <uri>model://olympus_description/urdf/meshes/BackRight_motorHousing.STL</uri>
          </mesh>
        </geometry>
      </visual>
    </link>
    <joint name='BackRight_hip_inner_motor11' type='revolute'>
      <pose relative_to='BackRight_motorHousing'>-0.0517 -0.05945 -1.1e-05 0 -0 0</pose>
      <parent>BackRight_motorHousing</parent>
      <child>BackRight_hip_inner</child>
      <axis>
        <xyz>0 1 0</xyz>
        <limit>
          <lower>-1.57</lower>
          <upper>1.57</upper>
          <effort>0</effort>
          <velocity>0</velocity>
        </limit>
        <dynamics>
          <spring_reference>0</spring_reference>
          <spring_stiffness>0</spring_stiffness>
        </dynamics>
      </axis>
    </joint>
    <link name='BackRight_hip_inner'>
      <pose relative_to='BackRight_hip_inner_motor11'>0 0 0 0 -0 0</pose>
      <inertial>
        <pose>0.000871 0.002638 -0.059532 0 -0 0</pose>
        <mass>0.0805</mass>
        <inertia>
          <ixx>0.00080743</ixx>
          <ixy>-7e-08</ixy>
          <ixz>-1.1e-05</ixz>
          <iyy>0.00081318</iyy>
          <iyz>4.71e-06</iyz>
          <izz>8.42e-06</izz>
        </inertia>
      </inertial>
      <collision name='BackRight_hip_inner_collision'>
        <pose>0 0 0 0 -0 0</pose>
        <geometry>
          <mesh>
            <scale>1 1 1</scale>
            <uri>model://olympus_description/urdf/meshes/BackRight_hip_inner.STL</uri>
          </mesh>
        </geometry>
      </collision>
      <visual name='BackRight_hip_inner_visual'>
        <pose>0 0 0 0 -0 0</pose>
        <geometry>
          <mesh>
            <scale>1 1 1</scale>
            <uri>model://olympus_description/urdf/meshes/BackRight_hip_inner.STL</uri>
          </mesh>
        </geometry>
      </visual>
    </link>
    <joint name='BackRight_shank_inner_knee' type='revolute'>
      <pose relative_to='BackRight_hip_inner'>0 -0.00075 -0.175 0 0.156107 0</pose>
      <parent>BackRight_hip_inner</parent>
      <child>BackRight_shank_inner</child>
      <axis>
        <xyz>0 1 0</xyz>
        <limit>
          <lower>-1.57</lower>
          <upper>1.57</upper>
          <effort>0</effort>
          <velocity>0</velocity>
        </limit>
        <dynamics>
          <spring_reference>0</spring_reference>
          <spring_stiffness>0</spring_stiffness>
        </dynamics>
      </axis>
    </joint>
    <link name='BackRight_shank_inner'>
      <pose relative_to='BackRight_shank_inner_knee'>0 0 0 0 -0 0</pose>
      <inertial>
        <pose>0.019639 1e-06 -0.194268 0 -0 0</pose>
        <mass>0.2193</mass>
        <inertia>
          <ixx>0.00834303</ixx>
          <ixy>-1.2977e-07</ixy>
          <ixz>-0.000695399</ixz>
          <iyy>0.00842368</iyy>
          <iyz>1.54795e-06</iyz>
          <izz>0.000119089</izz>
        </inertia>
      </inertial>
      <collision name='BackRight_shank_inner_collision'>
        <pose>0 0 0 0 -0 0</pose>
        <geometry>
          <mesh>
            <scale>1 1 1</scale>
            <uri>model://olympus_description/urdf/meshes/BackRight_shank_inner.STL</uri>
          </mesh>
        </geometry>
      </collision>
      <collision name='BackRight_shank_inner_fixed_joint_lump__BackRight_paw_collision_1'>
        <pose>0.034316 0 -0.318287 0 0.587746 3.14159</pose>
        <geometry>
          <mesh>
            <scale>1 1 1</scale>
            <uri>model://olympus_description/urdf/meshes/BackRight_paw.STL</uri>
          </mesh>
        </geometry>
      </collision>
      <visual name='BackRight_shank_inner_visual'>
        <pose>0 0 0 0 -0 0</pose>
        <geometry>
          <mesh>
            <scale>1 1 1</scale>
            <uri>model://olympus_description/urdf/meshes/BackRight_shank_inner.STL</uri>
          </mesh>
        </geometry>
      </visual>
      <visual name='BackRight_shank_inner_fixed_joint_lump__BackRight_paw_visual_1'>
        <pose>0.034316 0 -0.318287 0 0.587746 3.14159</pose>
        <geometry>
          <mesh>
            <scale>1 1 1</scale>
            <uri>model://olympus_description/urdf/meshes/BackRight_paw.STL</uri>
          </mesh>
        </geometry>
      </visual>
    </link>
    <joint name='BackRight_hip_outer_motor10' type='revolute'>
      <pose relative_to='BackRight_motorHousing'>-0.1417 -0.05945 -1.1e-05 0 -0 0</pose>
      <parent>BackRight_motorHousing</parent>
      <child>BackRight_hip_outer</child>
      <axis>
        <xyz>0 1 0</xyz>
        <limit>
          <lower>-1.57</lower>
          <upper>1.57</upper>
          <effort>0</effort>
          <velocity>0</velocity>
        </limit>
        <dynamics>
          <spring_reference>0</spring_reference>
          <spring_stiffness>0</spring_stiffness>
        </dynamics>
      </axis>
    </joint>
    <link name='BackRight_hip_outer'>
      <pose relative_to='BackRight_hip_outer_motor10'>0 0 0 0 -0 0</pose>
      <inertial>
        <pose>-0.000871 0.002633 -0.059284 0 -0 0</pose>
        <mass>0.081</mass>
        <inertia>
          <ixx>0.00080451</ixx>
          <ixy>7e-08</ixy>
          <ixz>1.098e-05</ixz>
          <iyy>0.00081035</iyy>
          <iyz>4.68e-06</iyz>
          <izz>8.51e-06</izz>
        </inertia>
      </inertial>
      <collision name='BackRight_hip_outer_collision'>
        <pose>0 0 0 0 -0 0</pose>
        <geometry>
          <mesh>
            <scale>1 1 1</scale>
            <uri>model://olympus_description/urdf/meshes/BackRight_hip_outer.STL</uri>
          </mesh>
        </geometry>
      </collision>
      <visual name='BackRight_hip_outer_visual'>
        <pose>0 0 0 0 -0 0</pose>
        <geometry>
          <mesh>
            <scale>1 1 1</scale>
            <uri>model://olympus_description/urdf/meshes/BackRight_hip_outer.STL</uri>
          </mesh>
        </geometry>
      </visual>
    </link>
    <joint name='BackRight_shank_outer_knee' type='revolute'>
      <pose relative_to='BackRight_hip_outer'>0 -0.00075 -0.175 0 -0.145529 0</pose>
      <parent>BackRight_hip_outer</parent>
      <child>BackRight_shank_outer</child>
      <axis>
        <xyz>0 1 0</xyz>
        <limit>
          <lower>-1.57</lower>
          <upper>1.57</upper>
          <effort>0</effort>
          <velocity>0</velocity>
        </limit>
        <dynamics>
          <spring_reference>0</spring_reference>
          <spring_stiffness>0</spring_stiffness>
        </dynamics>
      </axis>
    </joint>
    <link name='BackRight_shank_outer'>
      <pose relative_to='BackRight_shank_outer_knee'>0 0 0 0 -0 0</pose>
      <inertial>
        <pose>-0.004475 1e-06 -0.16466 0 -0 0</pose>
        <mass>0.1992</mass>
        <inertia>
          <ixx>0.0081046</ixx>
          <ixy>3e-08</ixy>
          <ixz>8.7e-05</ixz>
          <iyy>0.00810896</iyy>
          <iyz>1.7e-06</iyz>
          <izz>2.321e-05</izz>
        </inertia>
      </inertial>
      <collision name='BackRight_shank_outer_collision'>
        <pose>0 0 0 0 -0 0</pose>
        <geometry>
          <mesh>
            <scale>1 1 1</scale>
            <uri>model://olympus_description/urdf/meshes/BackRight_shank_outer.STL</uri>
          </mesh>
        </geometry>
      </collision>
      <visual name='BackRight_shank_outer_visual'>
        <pose>0 0 0 0 -0 0</pose>
        <geometry>
          <mesh>
            <scale>1 1 1</scale>
            <uri>model://olympus_description/urdf/meshes/BackRight_shank_outer.STL</uri>
          </mesh>
        </geometry>
      </visual>
    </link>
    <joint name='FrontLeft_motorHousing_hipAduction_motor3' type='revolute'>
      <pose relative_to='Body'>0.1433 0.105 0 0 -0 0</pose>
      <parent>Body</parent>
      <child>FrontLeft_motorHousing</child>
      <axis>
        <xyz>-1 0 0</xyz>
        <limit>
          <lower>-1.57</lower>
          <upper>1.57</upper>
          <effort>0</effort>
          <velocity>0</velocity>
        </limit>
        <dynamics>
          <spring_reference>0</spring_reference>
          <spring_stiffness>0</spring_stiffness>
        </dynamics>
      </axis>
    </joint>
    <link name='FrontLeft_motorHousing'>
      <pose relative_to='FrontLeft_motorHousing_hipAduction_motor3'>0 0 0 0 -0 0</pose>
      <inertial>
        <pose>0.092829 0.02913 0.000238 0 -0 0</pose>
        <mass>1.437</mass>
        <inertia>
          <ixx>0.00232895</ixx>
          <ixy>0.00418147</ixy>
          <ixz>3.194e-05</ixz>
          <iyy>0.0186199</iyy>
          <iyz>4.4e-06</iyz>
          <izz>0.0194884</izz>
        </inertia>
      </inertial>
      <collision name='FrontLeft_motorHousing_collision'>
        <pose>0 0 0 0 -0 0</pose>
        <geometry>
          <mesh>
            <scale>1 1 1</scale>
            <uri>model://olympus_description/urdf/meshes/FrontLeft_motorHousing.STL</uri>
          </mesh>
        </geometry>
      </collision>
      <visual name='FrontLeft_motorHousing_visual'>
        <pose>0 0 0 0 -0 0</pose>
        <geometry>
          <mesh>
            <scale>1 1 1</scale>
            <uri>model://olympus_description/urdf/meshes/FrontLeft_motorHousing.STL</uri>
          </mesh>
        </geometry>
      </visual>
    </link>
    <joint name='FrontLeft_hip_inner_motor2' type='revolute'>
      <pose relative_to='FrontLeft_motorHousing'>0.0517 0.05945 -1.1e-05 0 -0 0</pose>
      <parent>FrontLeft_motorHousing</parent>
      <child>FrontLeft_hip_inner</child>
      <axis>
        <xyz>0 1 0</xyz>
        <limit>
          <lower>-1.57</lower>
          <upper>1.57</upper>
          <effort>0</effort>
          <velocity>0</velocity>
        </limit>
        <dynamics>
          <spring_reference>0</spring_reference>
          <spring_stiffness>0</spring_stiffness>
        </dynamics>
      </axis>
    </joint>
    <link name='FrontLeft_hip_inner'>
      <pose relative_to='FrontLeft_hip_inner_motor2'>0 0 0 0 -0 0</pose>
      <inertial>
        <pose>-0.000871 -0.002638 -0.059532 0 -0 0</pose>
        <mass>0.081</mass>
        <inertia>
          <ixx>0.00080743</ixx>
          <ixy>-7e-08</ixy>
          <ixz>1.1e-05</ixz>
          <iyy>0.00081318</iyy>
          <iyz>-4.71e-06</iyz>
          <izz>3.7587e-06</izz>
        </inertia>
      </inertial>
      <collision name='FrontLeft_hip_inner_collision'>
        <pose>0 0 0 0 -0 0</pose>
        <geometry>
          <mesh>
            <scale>1 1 1</scale>
            <uri>model://olympus_description/urdf/meshes/FrontLeft_hip_inner.STL</uri>
          </mesh>
        </geometry>
      </collision>
      <visual name='FrontLeft_hip_inner_visual'>
        <pose>0 0 0 0 -0 0</pose>
        <geometry>
          <mesh>
            <scale>1 1 1</scale>
            <uri>model://olympus_description/urdf/meshes/FrontLeft_hip_inner.STL</uri>
          </mesh>
        </geometry>
      </visual>
    </link>
    <joint name='FrontLeft_shank_inner_knee' type='revolute'>
      <pose relative_to='FrontLeft_hip_inner'>0 0.00075 -0.175 0 -0.156107 0</pose>
      <parent>FrontLeft_hip_inner</parent>
      <child>FrontLeft_shank_inner</child>
      <axis>
        <xyz>0 1 0</xyz>
        <limit>
          <lower>-1.57</lower>
          <upper>1.57</upper>
          <effort>0</effort>
          <velocity>0</velocity>
        </limit>
        <dynamics>
          <spring_reference>0</spring_reference>
          <spring_stiffness>0</spring_stiffness>
        </dynamics>
      </axis>
    </joint>
    <link name='FrontLeft_shank_inner'>
      <pose relative_to='FrontLeft_shank_inner_knee'>0 0 0 0 -0 0</pose>
      <inertial>
        <pose>-0.019639 -1e-06 -0.194268 0 -0 0</pose>
        <mass>0.2193</mass>
        <inertia>
          <ixx>0.00833236</ixx>
          <ixy>-1.29947e-07</ixy>
          <ixz>0.000692523</ixz>
          <iyy>0.00841249</iyy>
          <iyz>-1.54774e-06</iyz>
          <izz>0.000106112</izz>
        </inertia>
      </inertial>
      <collision name='FrontLeft_shank_inner_collision'>
        <pose>0 0 0 0 -0 0</pose>
        <geometry>
          <mesh>
            <scale>1 1 1</scale>
            <uri>model://olympus_description/urdf/meshes/FrontLeft_shank_inner.STL</uri>
          </mesh>
        </geometry>
      </collision>
      <collision name='FrontLeft_shank_inner_fixed_joint_lump__FrontLeft_paw_collision_1'>
        <pose>-0.034316 0 -0.318287 -0 -0.587746 3.14159</pose>
        <geometry>
          <mesh>
            <scale>1 1 1</scale>
            <uri>model://olympus_description/urdf/meshes/FrontLeft_paw.STL</uri>
          </mesh>
        </geometry>
      </collision>
      <visual name='FrontLeft_shank_inner_visual'>
        <pose>0 0 0 0 -0 0</pose>
        <geometry>
          <mesh>
            <scale>1 1 1</scale>
            <uri>model://olympus_description/urdf/meshes/FrontLeft_shank_inner.STL</uri>
          </mesh>
        </geometry>
      </visual>
      <visual name='FrontLeft_shank_inner_fixed_joint_lump__FrontLeft_paw_visual_1'>
        <pose>-0.034316 0 -0.318287 -0 -0.587746 3.14159</pose>
        <geometry>
          <mesh>
            <scale>1 1 1</scale>
            <uri>model://olympus_description/urdf/meshes/FrontLeft_paw.STL</uri>
          </mesh>
        </geometry>
      </visual>
    </link>
    <joint name='FrontLeft_hip_outer_motor1' type='revolute'>
      <pose relative_to='FrontLeft_motorHousing'>0.1417 0.05945 -1.1e-05 0 -0 0</pose>
      <parent>FrontLeft_motorHousing</parent>
      <child>FrontLeft_hip_outer</child>
      <axis>
        <xyz>0 1 0</xyz>
        <limit>
          <lower>-1.57</lower>
          <upper>1.57</upper>
          <effort>0</effort>
          <velocity>0</velocity>
        </limit>
        <dynamics>
          <spring_reference>0</spring_reference>
          <spring_stiffness>0</spring_stiffness>
        </dynamics>
      </axis>
    </joint>
    <link name='FrontLeft_hip_outer'>
      <pose relative_to='FrontLeft_hip_outer_motor1'>0 0 0 0 -0 0</pose>
      <inertial>
        <pose>0.000871 -0.002633 -0.059284 0 -0 0</pose>
        <mass>0.0813</mass>
        <inertia>
          <ixx>0.00080451</ixx>
          <ixy>7e-08</ixy>
          <ixz>-1.097e-05</ixz>
          <iyy>0.00081035</iyy>
          <iyz>-4.68e-06</iyz>
          <izz>8.51e-06</izz>
        </inertia>
      </inertial>
      <collision name='FrontLeft_hip_outer_collision'>
        <pose>0 0 0 0 -0 0</pose>
        <geometry>
          <mesh>
            <scale>1 1 1</scale>
            <uri>model://olympus_description/urdf/meshes/FrontLeft_hip_outer.STL</uri>
          </mesh>
        </geometry>
      </collision>
      <visual name='FrontLeft_hip_outer_visual'>
        <pose>0 0 0 0 -0 0</pose>
        <geometry>
          <mesh>
            <scale>1 1 1</scale>
            <uri>model://olympus_description/urdf/meshes/FrontLeft_hip_outer.STL</uri>
          </mesh>
        </geometry>
      </visual>
    </link>
    <joint name='FrontLeft_shank_outer_knee' type='revolute'>
      <pose relative_to='FrontLeft_hip_outer'>0 0.00075 -0.175 0 0.145529 0</pose>
      <parent>FrontLeft_hip_outer</parent>
      <child>FrontLeft_shank_outer</child>
      <axis>
        <xyz>0 1 0</xyz>
        <limit>
          <lower>-1.57</lower>
          <upper>1.57</upper>
          <effort>0</effort>
          <velocity>0</velocity>
        </limit>
        <dynamics>
          <spring_reference>0</spring_reference>
          <spring_stiffness>0</spring_stiffness>
        </dynamics>
      </axis>
    </joint>
    <link name='FrontLeft_shank_outer'>
      <pose relative_to='FrontLeft_shank_outer_knee'>0 0 0 0 -0 0</pose>
      <inertial>
        <pose>0.004475 -1e-06 -0.16466 0 -0 0</pose>
        <mass>0.1992</mass>
        <inertia>
          <ixx>0.0081046</ixx>
          <ixy>3e-08</ixy>
          <ixz>-8.7e-05</ixz>
          <iyy>0.00810896</iyy>
          <iyz>-1.7e-06</iyz>
          <izz>2.321e-05</izz>
        </inertia>
      </inertial>
      <collision name='FrontLeft_shank_outer_collision'>
        <pose>0 0 0 0 -0 0</pose>
        <geometry>
          <mesh>
            <scale>1 1 1</scale>
            <uri>model://olympus_description/urdf/meshes/FrontLeft_shank_outer.STL</uri>
          </mesh>
        </geometry>
      </collision>
      <visual name='FrontLeft_shank_outer_visual'>
        <pose>0 0 0 0 -0 0</pose>
        <geometry>
          <mesh>
            <scale>1 1 1</scale>
            <uri>model://olympus_description/urdf/meshes/FrontLeft_shank_outer.STL</uri>
          </mesh>
        </geometry>
      </visual>
    </link>
    <joint name='FrontRight_motorHousing_hipAduction_motor6' type='revolute'>
      <pose relative_to='Body'>0.1433 -0.105 0 0 -0 0</pose>
      <parent>Body</parent>
      <child>FrontRight_motorHousing</child>
      <axis>
        <xyz>-1 0 0</xyz>
        <limit>
          <lower>-1.57</lower>
          <upper>1.57</upper>
          <effort>0</effort>
          <velocity>0</velocity>
        </limit>
        <dynamics>
          <spring_reference>0</spring_reference>
          <spring_stiffness>0</spring_stiffness>
        </dynamics>
      </axis>
    </joint>
    <link name='FrontRight_motorHousing'>
      <pose relative_to='FrontRight_motorHousing_hipAduction_motor6'>0 0 0 0 -0 0</pose>
      <inertial>
        <pose>0.092829 -0.02913 -0.000238 0 -0 0</pose>
        <mass>1.4374</mass>
        <inertia>
          <ixx>0.00232895</ixx>
          <ixy>-0.00418147</ixy>
          <ixz>-3.194e-05</ixz>
          <iyy>0.0186199</iyy>
          <iyz>4.4e-06</iyz>
          <izz>0.0194884</izz>
        </inertia>
      </inertial>
      <collision name='FrontRight_motorHousing_collision'>
        <pose>0 0 0 0 -0 0</pose>
        <geometry>
          <mesh>
            <scale>1 1 1</scale>
            <uri>model://olympus_description/urdf/meshes/FrontRight_motorHousing.STL</uri>
          </mesh>
        </geometry>
      </collision>
      <visual name='FrontRight_motorHousing_visual'>
        <pose>0 0 0 0 -0 0</pose>
        <geometry>
          <mesh>
            <scale>1 1 1</scale>
            <uri>model://olympus_description/urdf/meshes/FrontRight_motorHousing.STL</uri>
          </mesh>
        </geometry>
      </visual>
    </link>
    <joint name='FrontRight_hip_inner_motor5' type='revolute'>
      <pose relative_to='FrontRight_motorHousing'>0.0517 -0.05945 1.1e-05 0 -0 0</pose>
      <parent>FrontRight_motorHousing</parent>
      <child>FrontRight_hip_inner</child>
      <axis>
        <xyz>0 1 0</xyz>
        <limit>
          <lower>-1.57</lower>
          <upper>1.57</upper>
          <effort>0</effort>
          <velocity>0</velocity>
        </limit>
        <dynamics>
          <spring_reference>0</spring_reference>
          <spring_stiffness>0</spring_stiffness>
        </dynamics>
      </axis>
    </joint>
    <link name='FrontRight_hip_inner'>
      <pose relative_to='FrontRight_hip_inner_motor5'>0 0 0 0 -0 0</pose>
      <inertial>
        <pose>-0.000871 0.002633 -0.059284 0 -0 0</pose>
        <mass>0.081</mass>
        <inertia>
          <ixx>0.00080451</ixx>
          <ixy>7e-08</ixy>
          <ixz>1.098e-05</ixz>
          <iyy>0.00081035</iyy>
          <iyz>4.68e-06</iyz>
          <izz>8.51e-06</izz>
        </inertia>
      </inertial>
      <collision name='FrontRight_hip_inner_collision'>
        <pose>0 0 0 0 -0 0</pose>
        <geometry>
          <mesh>
            <scale>1 1 1</scale>
            <uri>model://olympus_description/urdf/meshes/FrontRight_hip_inner.STL</uri>
          </mesh>
        </geometry>
      </collision>
      <visual name='FrontRight_hip_inner_visual'>
        <pose>0 0 0 0 -0 0</pose>
        <geometry>
          <mesh>
            <scale>1 1 1</scale>
            <uri>model://olympus_description/urdf/meshes/FrontRight_hip_inner.STL</uri>
          </mesh>
        </geometry>
      </visual>
    </link>
    <joint name='FrontRight_shank_inner_knee' type='revolute'>
      <pose relative_to='FrontRight_hip_inner'>0 -0.00075 -0.175 0 -0.156107 0</pose>
      <parent>FrontRight_hip_inner</parent>
      <child>FrontRight_shank_inner</child>
      <axis>
        <xyz>0 1 0</xyz>
        <limit>
          <lower>-1.57</lower>
          <upper>1.57</upper>
          <effort>0</effort>
          <velocity>0</velocity>
        </limit>
        <dynamics>
          <spring_reference>0</spring_reference>
          <spring_stiffness>0</spring_stiffness>
        </dynamics>
      </axis>
    </joint>
    <link name='FrontRight_shank_inner'>
      <pose relative_to='FrontRight_shank_inner_knee'>0 0 0 0 -0 0</pose>
      <inertial>
        <pose>-0.019639 -1e-06 -0.194273 0 -0 0</pose>
        <mass>0.2192</mass>
        <inertia>
          <ixx>0.00833235</ixx>
          <ixy>-1.2977e-07</ixy>
          <ixz>0.000692525</ixz>
          <iyy>0.00841248</iyy>
          <iyz>-1.54794e-06</iyz>
          <izz>0.000106112</izz>
        </inertia>
      </inertial>
      <collision name='FrontRight_shank_inner_collision'>
        <pose>0 0 0 0 -0 0</pose>
        <geometry>
          <mesh>
            <scale>1 1 1</scale>
            <uri>model://olympus_description/urdf/meshes/FrontRight_shank_inner.STL</uri>
          </mesh>
        </geometry>
      </collision>
      <collision name='FrontRight_shank_inner_fixed_joint_lump__FrontRight_paw_collision_1'>
        <pose>-0.034316 0 -0.318287 -0 -0.587746 3.14159</pose>
        <geometry>
          <mesh>
            <scale>1 1 1</scale>
            <uri>model://olympus_description/urdf/meshes/FrontRight_paw.STL</uri>
          </mesh>
        </geometry>
      </collision>
      <visual name='FrontRight_shank_inner_visual'>
        <pose>0 0 0 0 -0 0</pose>
        <geometry>
          <mesh>
            <scale>1 1 1</scale>
            <uri>model://olympus_description/urdf/meshes/FrontRight_shank_inner.STL</uri>
          </mesh>
        </geometry>
      </visual>
      <visual name='FrontRight_shank_inner_fixed_joint_lump__FrontRight_paw_visual_1'>
        <pose>-0.034316 0 -0.318287 -0 -0.587746 3.14159</pose>
        <geometry>
          <mesh>
            <scale>1 1 1</scale>
            <uri>model://olympus_description/urdf/meshes/FrontRight_paw.STL</uri>
          </mesh>
        </geometry>
      </visual>
    </link>
    <joint name='FrontRight_hip_outer_motor4' type='revolute'>
      <pose relative_to='FrontRight_motorHousing'>0.1417 -0.05945 1.1e-05 0 -0 0</pose>
      <parent>FrontRight_motorHousing</parent>
      <child>FrontRight_hip_outer</child>
      <axis>
        <xyz>0 -1 0</xyz>
        <limit>
          <lower>-1.57</lower>
          <upper>1.57</upper>
          <effort>0</effort>
          <velocity>0</velocity>
        </limit>
        <dynamics>
          <spring_reference>0</spring_reference>
          <spring_stiffness>0</spring_stiffness>
        </dynamics>
      </axis>
    </joint>
    <link name='FrontRight_hip_outer'>
      <pose relative_to='FrontRight_hip_outer_motor4'>0 0 0 0 -0 0</pose>
      <inertial>
        <pose>0.000871 0.002638 -0.059532 0 -0 0</pose>
        <mass>0.0805</mass>
        <inertia>
          <ixx>0.00080743</ixx>
          <ixy>-7e-08</ixy>
          <ixz>-1.1e-05</ixz>
          <iyy>0.00081318</iyy>
          <iyz>4.71e-06</iyz>
          <izz>8.42e-06</izz>
        </inertia>
      </inertial>
      <collision name='FrontRight_hip_outer_collision'>
        <pose>0 0 0 0 -0 0</pose>
        <geometry>
          <mesh>
            <scale>1 1 1</scale>
            <uri>model://olympus_description/urdf/meshes/FrontRight_hip_outer.STL</uri>
          </mesh>
        </geometry>
      </collision>
      <visual name='FrontRight_hip_outer_visual'>
        <pose>0 0 0 0 -0 0</pose>
        <geometry>
          <mesh>
            <scale>1 1 1</scale>
            <uri>model://olympus_description/urdf/meshes/FrontRight_hip_outer.STL</uri>
          </mesh>
        </geometry>
      </visual>
    </link>
    <joint name='FrontRight_shank_outer_knee' type='revolute'>
      <pose relative_to='FrontRight_hip_outer'>0 -0.00075 -0.175 0 0.145529 0</pose>
      <parent>FrontRight_hip_outer</parent>
      <child>FrontRight_shank_outer</child>
      <axis>
        <xyz>0 1 0</xyz>
        <limit>
          <lower>-1.57</lower>
          <upper>1.57</upper>
          <effort>0</effort>
          <velocity>0</velocity>
        </limit>
        <dynamics>
          <spring_reference>0</spring_reference>
          <spring_stiffness>0</spring_stiffness>
        </dynamics>
      </axis>
    </joint>
    <link name='FrontRight_shank_outer'>
      <pose relative_to='FrontRight_shank_outer_knee'>0 0 0 0 -0 0</pose>
      <inertial>
        <pose>0.004475 -1e-06 -0.16466 0 -0 0</pose>
        <mass>0.1992</mass>
        <inertia>
          <ixx>0.0081046</ixx>
          <ixy>3e-08</ixy>
          <ixz>-8.7e-05</ixz>
          <iyy>0.00810896</iyy>
          <iyz>-1.7e-06</iyz>
          <izz>2.321e-05</izz>
        </inertia>
      </inertial>
      <collision name='FrontRight_shank_outer_collision'>
        <pose>0 0 0 0 -0 0</pose>
        <geometry>
          <mesh>
            <scale>1 1 1</scale>
            <uri>model://olympus_description/urdf/meshes/FrontRight_shank_outer.STL</uri>
          </mesh>
        </geometry>
      </collision>
      <visual name='FrontRight_shank_outer_visual'>
        <pose>0 0 0 0 -0 0</pose>
        <geometry>
          <mesh>
            <scale>1 1 1</scale>
            <uri>model://olympus_description/urdf/meshes/FrontRight_shank_outer.STL</uri>
          </mesh>
        </geometry>
      </visual>
    </link>
    <frame name='BackLeft_paw' attached_to='BackLeft_shank_inner'>
      <pose>0.034316 0 -0.318287 -0 0.587746 -3.14159</pose>
    </frame>
    <frame name='BackLeft_paw' attached_to='BackLeft_paw'/>
    <frame name='BackRight_paw' attached_to='BackRight_shank_inner'>
      <pose>0.034316 0 -0.318287 0 0.587746 3.14159</pose>
    </frame>
    <frame name='BackRight_paw' attached_to='BackRight_paw'/>
    <frame name='FrontLeft_paw' attached_to='FrontLeft_shank_inner'>
      <pose>-0.034316 0 -0.318287 -0 -0.587746 3.14159</pose>
    </frame>
    <frame name='FrontLeft_paw' attached_to='FrontLeft_paw'/>
    <frame name='FrontRight_paw' attached_to='FrontRight_shank_inner'>
      <pose>-0.034316 0 -0.318287 -0 -0.587746 3.14159</pose>
    </frame>
    <frame name='FrontRight_paw' attached_to='FrontRight_paw'/>
  </model>
</sdf>
