<?xml version="1.0" ?>
<robot
  name="olympus_description">


  <link
    name="Body">
    <inertial>
      <origin
        xyz="-0.0093903 0.00018696 0.011109"
        rpy="0 0 0" />
      <mass
        value="5.679" />
      <inertia
        ixx="0.05428615"
        ixy="-0.00110179"
        ixz="-0.0017034"
        iyy="0.15070598"
        iyz="0.00013585"
        izz="0.19574722" />
    </inertial>
    <visual>
      <origin
        xyz="0 0 0"
        rpy="0 0 0" />
      <geometry>
        <mesh
          filename="package://olympus_description/urdf/meshes/Body.dae" />
      </geometry>
      <material
        name="">
        <color
          rgba="0.79216 0.81961 0.93333 1" />
      </material>
    </visual>
    <collision>
      <origin
        xyz="0 0 0"
        rpy="0 0 0" />
      <geometry>
        <mesh
          filename="package://olympus_description/urdf/meshes/Body.dae" />
      </geometry>
    </collision>
  </link>
  



  
  

  
  <link
    name="FrontLeft_motorHousing">
    <inertial>
      <origin
        xyz="0.092829 0.02913 0.00023828"
        rpy="0 0 0" />
      <mass
        value="1.437" />
      <inertia
        ixx="0.00232895"
        ixy="0.00418147"
        ixz="3.194E-05"
        iyy="0.01861991"
        iyz="4.4E-06"
        izz="0.01948836" />
    </inertial>
    <visual>
      <origin
        xyz="0 0 0"
        rpy="0 0 0" />
      <geometry>
        <mesh
          filename="package://olympus_description/urdf/meshes/FrontLeft_motorHousing.dae" />
      </geometry>
      <material
        name="">
        <color
          rgba="0.79216 0.81961 0.93333 1" />
      </material>
    </visual>
    <collision>
      <origin
        xyz="0 0 0"
        rpy="0 0 0" />
      <geometry>
        <mesh
          filename="package://olympus_description/urdf/meshes/FrontLeft_motorHousing.dae" />
      </geometry>
    </collision>
  </link>
  <joint
    name="FrontLeft_motorHousing_hipAduction_motor"
    type="revolute">
    <origin
      xyz="0.143300000000002 0.104999999999997 0"
      rpy="0 0 0" />
    <parent
      link="Body" />
    <child
      link="FrontLeft_motorHousing" />
    <axis
      xyz="-1 0 0" />
    <limit
      lower="-1.57"
      upper="1.57"
      effort="0"
      velocity="0" />
  </joint>
  <link
    name="FrontLeft_hip_inner">
    <inertial>
      <origin
        xyz="-0.00087111 -0.0026375 -0.059532"
        rpy="0 0 0" />
      <mass
        value="0.081" />
      <inertia
        ixx="0.00080743"
        ixy="-7E-08"
        ixz="1.1E-05"
        iyy="0.00081318"
        iyz="-4.71E-06"
        izz="3.7587E-06" />
    </inertial>
    <visual>
      <origin
        xyz="0 0 0"
        rpy="0 0 0" />
      <geometry>
        <mesh
          filename="package://olympus_description/urdf/meshes/FrontLeft_hip_inner.dae" />
      </geometry>
      <material
        name="">
        <color
          rgba="0.79216 0.81961 0.93333 1" />
      </material>
    </visual>
    <collision>
      <origin
        xyz="0 0 0"
        rpy="0 0 0" />
      <geometry>
        <mesh
          filename="package://olympus_description/urdf/meshes/FrontLeft_hip_inner.dae" />
      </geometry>
    </collision>
  </link>
  <joint
    name="FrontLeft_hip_inner_motor"
    type="revolute">
    <origin
      xyz="0.051699999999999 0.0594499999999993 -1.1338370204463E-05"
      rpy="0 0 0" />
    <parent
      link="FrontLeft_motorHousing" />
    <child
      link="FrontLeft_hip_inner" />
    <axis
      xyz="0 1 0" />
    <limit
      lower="-1.57"
      upper="1.57"
      effort="0"
      velocity="0" />
  </joint>
  <link
    name="FrontLeft_shank_inner">
    <inertial>
      <origin
        xyz="-0.018257 -5.7848E-07 -0.18193"
        rpy="0 0 0" />
      <mass
        value="0.1993" />
      <inertia
        ixx="0.00799515"
        ixy="-1.3E-07"
        ixz="0.00072855"
        iyy="0.00807089"
        iyz="-1.55E-06"
        izz="9.64E-05" />
    </inertial>
    <visual>
      <origin
        xyz="0 0 0"
        rpy="0 0 0" />
      <geometry>
        <mesh
          filename="package://olympus_description/urdf/meshes/FrontLeft_shank_inner.dae" />
      </geometry>
      <material
        name="">
        <color
          rgba="0.79216 0.81961 0.93333 1" />
      </material>
    </visual>
    <collision>
      <origin
        xyz="0 0 0"
        rpy="0 0 0" />
      <geometry>
        <mesh
          filename="package://olympus_description/urdf/meshes/FrontLeft_shank_inner.dae" />
      </geometry>
    </collision>
  </link>
  <joint
    name="FrontLeft_shank_inner_knee"
    type="revolute">
    <origin
      xyz="0 0.000750000000007855 -0.175000000000014"
      rpy="0 -0.156107447167547 0" />
    <parent
      link="FrontLeft_hip_inner" />
    <child
      link="FrontLeft_shank_inner" />
    <axis
      xyz="0 1 0" />
    <limit
      lower="-1.57"
      upper="1.57"
      effort="0"
      velocity="0" />
  </joint>
  <link
    name="FrontLeft_paw">
    <inertial>
      <origin
        xyz="-0.00016141 -2.5484E-07 0.0013973"
        rpy="0 0 0" />
      <mass
        value="0.02" />
      <inertia
        ixx="3.73E-06"
        ixy="-2.6396E-10"
        ixz="-2E-08"
        iyy="4.78E-06"
        iyz="-7.8092E-11"
        izz="6.37E-06" />
    </inertial>
    <visual>
      <origin
        xyz="0 0 0"
        rpy="0 0 0" />
      <geometry>
        <mesh
          filename="package://olympus_description/urdf/meshes/FrontLeft_paw.dae" />
      </geometry>
      <material
        name="">
        <color
          rgba="0.79216 0.81961 0.93333 1" />
      </material>
    </visual>
    <collision>
      <origin
        xyz="0 0 0"
        rpy="0 0 0" />
      <geometry>
        <mesh
          filename="package://olympus_description/urdf/meshes/FrontLeft_paw.dae" />
      </geometry>
    </collision>
  </link>
  <joint
    name="FrontLeft_paw_joint"
    type="fixed">
    <origin
      xyz="-0.034316172849209 0 -0.318287120023731"
      rpy="0 -0.587745839939292 3.14159265358979" />
    <parent
      link="FrontLeft_shank_inner" />
    <child
      link="FrontLeft_paw" />
    <axis
      xyz="0 0 0" />
  </joint>

  <link
    name="FrontRight_motorHousing">
    <inertial>
      <origin
        xyz="0.092829 -0.02913 -0.00023828"
        rpy="0 0 0" />
      <mass
        value="1.4374" />
      <inertia
        ixx="0.00232895"
        ixy="-0.00418147"
        ixz="-3.194E-05"
        iyy="0.01861991"
        iyz="4.4E-06"
        izz="0.01948836" />
    </inertial>
    <visual>
      <origin
        xyz="0 0 0"
        rpy="0 0 0" />
      <geometry>
        <mesh
          filename="package://olympus_description/urdf/meshes/FrontRight_motorHousing.dae" />
      </geometry>
      <material
        name="">
        <color
          rgba="0.79216 0.81961 0.93333 1" />
      </material>
    </visual>
    <collision>
      <origin
        xyz="0 0 0"
        rpy="0 0 0" />
      <geometry>
        <mesh
          filename="package://olympus_description/urdf/meshes/FrontRight_motorHousing.dae" />
      </geometry>
    </collision>
  </link>
  <joint
    name="FrontRight_motorHousing_hipAduction_motor"
    type="revolute">
    <origin
      xyz="0.143300000000001 -0.104999999999999 0"
      rpy="0 0 0" />
    <parent
      link="Body" />
    <child
      link="FrontRight_motorHousing" />
    <axis
      xyz="-1 0 0" />
    <limit
      lower="-1.57"
      upper="1.57"
      effort="0"
      velocity="0" />
  </joint>
  <link
    name="FrontRight_hip_inner">
    <inertial>
      <origin
        xyz="-0.00087097 0.0026333 -0.059284"
        rpy="0 0 0" />
      <mass
        value="0.081" />
      <inertia
        ixx="0.00080451"
        ixy="7E-08"
        ixz="1.098E-05"
        iyy="0.00081035"
        iyz="4.68E-06"
        izz="8.51E-06" />
    </inertial>
    <visual>
      <origin
        xyz="0 0 0"
        rpy="0 0 0" />
      <geometry>
        <mesh
          filename="package://olympus_description/urdf/meshes/FrontRight_hip_inner.dae" />
      </geometry>
      <material
        name="">
        <color
          rgba="0.79216 0.81961 0.93333 1" />
      </material>
    </visual>
    <collision>
      <origin
        xyz="0 0 0"
        rpy="0 0 0" />
      <geometry>
        <mesh
          filename="package://olympus_description/urdf/meshes/FrontRight_hip_inner.dae" />
      </geometry>
    </collision>
  </link>
  <joint
    name="FrontRight_hip_inner_motor"
    type="revolute">
    <origin
      xyz="0.0517000000000003 -0.0594500000000019 1.13383701956029E-05"
      rpy="0 0 0" />
    <parent
      link="FrontRight_motorHousing" />
    <child
      link="FrontRight_hip_inner" />
    <axis
      xyz="0 1 0" />
    <limit
      lower="-1.57"
      upper="1.57"
      effort="0"
      velocity="0" />
  </joint>
  <link
    name="FrontRight_shank_inner">
    <inertial>
      <origin
        xyz="-0.018257 -5.8199E-07 -0.18193"
        rpy="0 0 0" />
      <mass
        value="0.1992" />
      <inertia
        ixx="0.00799515"
        ixy="-1.3E-07"
        ixz="0.00072855"
        iyy="0.00807089"
        iyz="-1.55E-06"
        izz="9.64E-05" />
    </inertial>
    <visual>
      <origin
        xyz="0 0 0"
        rpy="0 0 0" />
      <geometry>
        <mesh
          filename="package://olympus_description/urdf/meshes/FrontRight_shank_inner.dae" />
      </geometry>
      <material
        name="">
        <color
          rgba="0.79216 0.81961 0.93333 1" />
      </material>
    </visual>
    <collision>
      <origin
        xyz="0 0 0"
        rpy="0 0 0" />
      <geometry>
        <mesh
          filename="package://olympus_description/urdf/meshes/FrontRight_shank_inner.dae" />
      </geometry>
    </collision>
  </link>
  <joint
    name="FrontRight_shank_inner_knee"
    type="revolute">
    <origin
      xyz="0 -0.000749999999992201 -0.174999999999991"
      rpy="0 -0.156107447167536 0" />
    <parent
      link="FrontRight_hip_inner" />
    <child
      link="FrontRight_shank_inner" />
    <axis
      xyz="0 1 0" />
    <limit
      lower="-1.57"
      upper="1.57"
      effort="0"
      velocity="0" />
  </joint>
  <link
    name="FrontRight_paw">
    <inertial>
      <origin
        xyz="-0.00016141 -2.5484E-07 0.0013973"
        rpy="0 0 0" />
      <mass
        value="0.02" />
      <inertia
        ixx="3.73E-06"
        ixy="0"
        ixz="-2E-08"
        iyy="4.78E-06"
        iyz="0"
        izz="6.37E-06" />
    </inertial>
    <visual>
      <origin
        xyz="0 0 0"
        rpy="0 0 0" />
      <geometry>
        <mesh
          filename="package://olympus_description/urdf/meshes/FrontRight_paw.dae" />
      </geometry>
      <material
        name="">
        <color
          rgba="0.79216 0.81961 0.93333 1" />
      </material>
    </visual>
    <collision>
      <origin
        xyz="0 0 0"
        rpy="0 0 0" />
      <geometry>
        <mesh
          filename="package://olympus_description/urdf/meshes/FrontRight_paw.dae" />
      </geometry>
    </collision>
  </link>
  <joint
    name="FrontRight_paw_joint"
    type="fixed">
    <origin
      xyz="-0.0343161728492139 0 -0.318287120023735"
      rpy="0 -0.587745839939292 3.14159265358979" />
    <parent
      link="FrontRight_shank_inner" />
    <child
      link="FrontRight_paw" />
    <axis
      xyz="0 0 0" />
  </joint>
  <link
    name="BackLeft_motorHousing">
    <inertial>
      <origin
        xyz="-0.092829 0.02913 -0.00023828"
        rpy="0 0 0" />
      <mass
        value="1.437" />
      <inertia
        ixx="0.00232895"
        ixy="-0.00418147"
        ixz="3.194E-05"
        iyy="0.01861991"
        iyz="-4.4E-06"
        izz="0.01948836" />
    </inertial>
    <visual>
      <origin
        xyz="0 0 0"
        rpy="0 0 0" />
      <geometry>
        <mesh
          filename="package://olympus_description/urdf/meshes/BackLeft_motorHousing.dae" />
      </geometry>
      <material
        name="">
        <color
          rgba="0.79216 0.81961 0.93333 1" />
      </material>
    </visual>
    <collision>
      <origin
        xyz="0 0 0"
        rpy="0 0 0" />
      <geometry>
        <mesh
          filename="package://olympus_description/urdf/meshes/BackLeft_motorHousing.dae" />
      </geometry>
    </collision>
  </link>
  <joint
    name="BackLeft_motorHousing_hipAduction_motor"
    type="revolute">
    <origin
      xyz="-0.143300000000002 0.149999999999995 0"
      rpy="0 0 0" />
    <parent
      link="Body" />
    <child
      link="BackLeft_motorHousing" />
    <axis
      xyz="1 0 0" />
    <limit
      lower="-1.57"
      upper="1.57"
      effort="0"
      velocity="0" />
  </joint>
  <link
    name="BackLeft_hip_inner">
    <inertial>
      <origin
        xyz="0.00087097 -0.0026333 -0.059284"
        rpy="0 0 0" />
      <mass
        value="0.081" />
      <inertia
        ixx="0.00080451"
        ixy="7E-08"
        ixz="-1.097E-05"
        iyy="0.00081035"
        iyz="-4.68E-06"
        izz="8.51E-06" />
    </inertial>
    <visual>
      <origin
        xyz="0 0 0"
        rpy="0 0 0" />
      <geometry>
        <mesh
          filename="package://olympus_description/urdf/meshes/BackLeft_hip_inner.dae" />
      </geometry>
      <material
        name="">
        <color
          rgba="0.79216 0.81961 0.93333 1" />
      </material>
    </visual>
    <collision>
      <origin
        xyz="0 0 0"
        rpy="0 0 0" />
      <geometry>
        <mesh
          filename="package://olympus_description/urdf/meshes/BackLeft_hip_inner.dae" />
      </geometry>
    </collision>
  </link>
  <joint
    name="BackLeft_hip_inner_motor"
    type="revolute">
    <origin
      xyz="-0.0516999999999978 0.0594500000000004 1.13383700547322E-05"
      rpy="0 0 0" />
    <parent
      link="BackLeft_motorHousing" />
    <child
      link="BackLeft_hip_inner" />
    <axis
      xyz="0 -1 0" />
    <limit
      lower="-1.57"
      upper="1.57"
      effort="0"
      velocity="0" />
  </joint>
  <link
    name="BackLeft_shank_inner">
    <inertial>
      <origin
        xyz="0.018257 5.8939E-07 -0.18193"
        rpy="0 0 0" />
      <mass
        value="0.1993" />
      <inertia
        ixx="0.00799515"
        ixy="-1.3E-07"
        ixz="-0.00072855"
        iyy="0.00807089"
        iyz="1.55E-06"
        izz="9.64E-05" />
    </inertial>
    <visual>
      <origin
        xyz="0 0 0"
        rpy="0 0 0" />
      <geometry>
        <mesh
          filename="package://olympus_description/urdf/meshes/BackLeft_shank_inner.dae" />
      </geometry>
      <material
        name="">
        <color
          rgba="0.79216 0.81961 0.93333 1" />
      </material>
    </visual>
    <collision>
      <origin
        xyz="0 0 0"
        rpy="0 0 0" />
      <geometry>
        <mesh
          filename="package://olympus_description/urdf/meshes/BackLeft_shank_inner.dae" />
      </geometry>
    </collision>
  </link>
  <joint
    name="BackLeft_shank_inner_knee"
    type="revolute">
    <origin
      xyz="0 0.000749999999984485 -0.174999999999858"
      rpy="0 0.156107447167218 0" />
    <parent
      link="BackLeft_hip_inner" />
    <child
      link="BackLeft_shank_inner" />
    <axis
      xyz="0 1 0" />
    <limit
      lower="-1.57"
      upper="1.57"
      effort="0"
      velocity="0" />
  </joint>
  <link
    name="BackLeft_paw">
    <inertial>
      <origin
        xyz="0.00016141 2.5484E-07 0.0013973"
        rpy="0 0 0" />
      <mass
        value="0.02" />
      <inertia
        ixx="1.236E-05"
        ixy="0"
        ixz="5E-08"
        iyy="1.587E-05"
        iyz="0"
        izz="2.129E-05" />
    </inertial>
    <visual>
      <origin
        xyz="0 0 0"
        rpy="0 0 0" />
      <geometry>
        <mesh
          filename="package://olympus_description/urdf/meshes/BackLeft_paw.dae" />
      </geometry>
      <material
        name="">
        <color
          rgba="0.79216 0.81961 0.93333 1" />
      </material>
    </visual>
    <collision>
      <origin
        xyz="0 0 0"
        rpy="0 0 0" />
      <geometry>
        <mesh
          filename="package://olympus_description/urdf/meshes/BackLeft_paw.dae" />
      </geometry>
    </collision>
  </link>
  <joint
    name="BackLeft_paw_joint"
    type="fixed">
    <origin
      xyz="0.0343161728493504 0 -0.318287120023714"
      rpy="0 0.587745839939292 -3.14159265358976" />
    <parent
      link="BackLeft_shank_inner" />
    <child
      link="BackLeft_paw" />
    <axis
      xyz="0 0 0" />
  </joint>
  <link
    name="BackRight_motorHousing">
    <inertial>
      <origin
        xyz="-0.092829 -0.02913 0.00023828"
        rpy="0 0 0" />
      <mass
        value="1.437" />
      <inertia
        ixx="0.00232895"
        ixy="0.00418147"
        ixz="-3.194E-05"
        iyy="0.01861991"
        iyz="-4.4E-06"
        izz="0.01948836" />
    </inertial>
    <visual>
      <origin
        xyz="0 0 0"
        rpy="0 0 0" />
      <geometry>
        <mesh
          filename="package://olympus_description/urdf/meshes/BackRight_motorHousing.dae" />
      </geometry>
      <material
        name="">
        <color
          rgba="0.79216 0.81961 0.93333 1" />
      </material>
    </visual>
    <collision>
      <origin
        xyz="0 0 0"
        rpy="0 0 0" />
      <geometry>
        <mesh
          filename="package://olympus_description/urdf/meshes/BackRight_motorHousing.dae" />
      </geometry>
    </collision>
  </link>
  <joint
    name="BackRight_motorHousing_hipAduction_motor12"
    type="revolute">
    <origin
      xyz="-0.1433 -0.150000000000002 0"
      rpy="0 0 0" />
    <parent
      link="Body" />
    <child
      link="BackRight_motorHousing" />
    <axis
      xyz="1 0 0" />
    <limit
      lower="-1.57"
      upper="1.57"
      effort="0"
      velocity="0" />
  </joint>
  <link
    name="BackRight_hip_inner">
    <inertial>
      <origin
        xyz="0.00087111 0.0026375 -0.059532"
        rpy="0 0 0" />
      <mass
        value="0.0805" />
      <inertia
        ixx="0.00080743"
        ixy="-7E-08"
        ixz="-1.1E-05"
        iyy="0.00081318"
        iyz="4.71E-06"
        izz="8.42E-06" />
    </inertial>
    <visual>
      <origin
        xyz="0 0 0"
        rpy="0 0 0" />
      <geometry>
        <mesh
          filename="package://olympus_description/urdf/meshes/BackRight_hip_inner.dae" />
      </geometry>
      <material
        name="">
        <color
          rgba="0.79216 0.81961 0.93333 1" />
      </material>
    </visual>
    <collision>
      <origin
        xyz="0 0 0"
        rpy="0 0 0" />
      <geometry>
        <mesh
          filename="package://olympus_description/urdf/meshes/BackRight_hip_inner.dae" />
      </geometry>
    </collision>
  </link>
  <joint
    name="BackRight_hip_inner_motor11"
    type="revolute">
    <origin
      xyz="-0.0517000000000002 -0.0594500000000022 -1.1338370431546E-05"
      rpy="0 0 0" />
    <parent
      link="BackRight_motorHousing" />
    <child
      link="BackRight_hip_inner" />
    <axis
      xyz="0 1 0" />
    <limit
      lower="-1.57"
      upper="1.57"
      effort="0"
      velocity="0" />
  </joint>
  <link
    name="BackRight_shank_inner">
    <inertial>
      <origin
        xyz="0.018257 5.8084E-07 -0.18193"
        rpy="0 0 0" />
      <mass
        value="0.1993" />
      <inertia
        ixx="0.00799515"
        ixy="-1.3E-07"
        ixz="-0.00072855"
        iyy="0.00807089"
        iyz="1.55E-06"
        izz="9.64E-05" />
    </inertial>
    <visual>
      <origin
        xyz="0 0 0"
        rpy="0 0 0" />
      <geometry>
        <mesh
          filename="package://olympus_description/urdf/meshes/BackRight_shank_inner.dae" />
      </geometry>
      <material
        name="">
        <color
          rgba="0.79216 0.81961 0.93333 1" />
      </material>
    </visual>
    <collision>
      <origin
        xyz="0 0 0"
        rpy="0 0 0" />
      <geometry>
        <mesh
          filename="package://olympus_description/urdf/meshes/BackRight_shank_inner.dae" />
      </geometry>
    </collision>
  </link>
  <joint
    name="BackRight_shank_inner_knee"
    type="revolute">
    <origin
      xyz="0 -0.000749999999271611 -0.174999999999955"
      rpy="0 0.156107447164923 0" />
    <parent
      link="BackRight_hip_inner" />
    <child
      link="BackRight_shank_inner" />
    <axis
      xyz="0 1 0" />
    <limit
      lower="-1.57"
      upper="1.57"
      effort="0"
      velocity="0" />
  </joint>
  <link
    name="BackRight_paw">
    <inertial>
      <origin
        xyz="0.00016141 2.5484E-07 0.0013973"
        rpy="0 0 0" />
      <mass
        value="0.02" />
      <inertia
        ixx="1.245E-05"
        ixy="0"
        ixz="6E-08"
        iyy="1.597E-05"
        iyz="0"
        izz="2.129E-05" />
    </inertial>
    <visual>
      <origin
        xyz="0 0 0"
        rpy="0 0 0" />
      <geometry>
        <mesh
          filename="package://olympus_description/urdf/meshes/BackRight_paw.dae" />
      </geometry>
      <material
        name="">
        <color
          rgba="0.79216 0.81961 0.93333 1" />
      </material>
    </visual>
    <collision>
      <origin
        xyz="0 0 0"
        rpy="0 0 0" />
      <geometry>
        <mesh
          filename="package://olympus_description/urdf/meshes/BackRight_paw.dae" />
      </geometry>
    </collision>
  </link>
  <joint
    name="BackRight_paw_joint"
    type="fixed">
    <origin
      xyz="0.0343161728494181 0 -0.318287120023818"
      rpy="0 0.58774583993929 3.14159265358979" />
    <parent
      link="BackRight_shank_inner" />
    <child
      link="BackRight_paw" />
    <axis
      xyz="0 0 0" />
  </joint>

</robot>